2025-10-13 14:18:46,168 [INFO] Starting p2p chat app. SHARED_KEY set: no
2025-10-13 14:18:46,216 [INFO] Bound to saved port 14447
2025-10-13 14:24:53,832 [INFO] Starting p2p chat app. SHARED_KEY set: no
2025-10-13 14:24:53,876 [INFO] Bound to saved port 14447
2025-10-13 14:26:27,189 [INFO] Received message from 192.168.0.107
2025-10-13 14:26:27,594 [DEBUG] Received PING from 192.168.0.107
2025-10-13 14:26:29,002 [ERROR] ping_peer failed for 192.168.0.107:0
Traceback (most recent call last):
  File "C:\Users\ASUS\OneDrive\Documents\chat_app1\chat_app_unified.py", line 506, in ping_peer
    s.connect((ip, port))
    ~~~~~~~~~^^^^^^^^^^^^
OSError: [WinError 10049] The requested address is not valid in its context
2025-10-13 14:26:32,657 [DEBUG] Received PING from 192.168.0.107
2025-10-13 14:26:34,036 [ERROR] ping_peer failed for 192.168.0.107:0
Traceback (most recent call last):
  File "C:\Users\ASUS\OneDrive\Documents\chat_app1\chat_app_unified.py", line 506, in ping_peer
    s.connect((ip, port))
    ~~~~~~~~~^^^^^^^^^^^^
OSError: [WinError 10049] The requested address is not valid in its context
2025-10-13 14:26:37,722 [DEBUG] Received PING from 192.168.0.107
2025-10-13 14:26:39,038 [ERROR] ping_peer failed for 192.168.0.107:0
Traceback (most recent call last):
  File "C:\Users\ASUS\OneDrive\Documents\chat_app1\chat_app_unified.py", line 506, in ping_peer
    s.connect((ip, port))
    ~~~~~~~~~^^^^^^^^^^^^
OSError: [WinError 10049] The requested address is not valid in its context
2025-10-13 14:26:41,291 [ERROR] send_message failed to 192.168.0.107:0
Traceback (most recent call last):
  File "C:\Users\ASUS\OneDrive\Documents\chat_app1\chat_app_unified.py", line 479, in send_message
    s.connect((ip, port))
    ~~~~~~~~~^^^^^^^^^^^^
OSError: [WinError 10049] The requested address is not valid in its context
2025-10-13 14:26:41,293 [WARNING] Send to 192.168.0.107 failed
2025-10-13 14:26:42,795 [DEBUG] Received PING from 192.168.0.107
2025-10-13 14:26:44,044 [ERROR] ping_peer failed for 192.168.0.107:0
Traceback (most recent call last):
  File "C:\Users\ASUS\OneDrive\Documents\chat_app1\chat_app_unified.py", line 506, in ping_peer
    s.connect((ip, port))
    ~~~~~~~~~^^^^^^^^^^^^
OSError: [WinError 10049] The requested address is not valid in its context
2025-10-13 14:26:47,878 [DEBUG] Received PING from 192.168.0.107
2025-10-13 14:26:49,049 [ERROR] ping_peer failed for 192.168.0.107:0
Traceback (most recent call last):
  File "C:\Users\ASUS\OneDrive\Documents\chat_app1\chat_app_unified.py", line 506, in ping_peer
    s.connect((ip, port))
    ~~~~~~~~~^^^^^^^^^^^^
OSError: [WinError 10049] The requested address is not valid in its context
2025-10-13 14:26:49,571 [ERROR] send_message failed to 192.168.0.107:0
Traceback (most recent call last):
  File "C:\Users\ASUS\OneDrive\Documents\chat_app1\chat_app_unified.py", line 479, in send_message
    s.connect((ip, port))
    ~~~~~~~~~^^^^^^^^^^^^
OSError: [WinError 10049] The requested address is not valid in its context
2025-10-13 14:26:49,573 [WARNING] Send to 192.168.0.107 failed
2025-10-13 14:26:52,966 [DEBUG] Received PING from 192.168.0.107
2025-10-13 14:26:54,052 [ERROR] ping_peer failed for 192.168.0.107:0
Traceback (most recent call last):
  File "C:\Users\ASUS\OneDrive\Documents\chat_app1\chat_app_unified.py", line 506, in ping_peer
    s.connect((ip, port))
    ~~~~~~~~~^^^^^^^^^^^^
OSError: [WinError 10049] The requested address is not valid in its context
2025-10-13 14:26:58,046 [DEBUG] Received PING from 192.168.0.107
2025-10-13 14:26:59,055 [ERROR] ping_peer failed for 192.168.0.107:0
Traceback (most recent call last):
  File "C:\Users\ASUS\OneDrive\Documents\chat_app1\chat_app_unified.py", line 506, in ping_peer
    s.connect((ip, port))
    ~~~~~~~~~^^^^^^^^^^^^
OSError: [WinError 10049] The requested address is not valid in its context
2025-10-13 14:27:03,369 [DEBUG] Received PING from 192.168.0.107
2025-10-13 14:27:04,061 [ERROR] ping_peer failed for 192.168.0.107:0
Traceback (most recent call last):
  File "C:\Users\ASUS\OneDrive\Documents\chat_app1\chat_app_unified.py", line 506, in ping_peer
    s.connect((ip, port))
    ~~~~~~~~~^^^^^^^^^^^^
OSError: [WinError 10049] The requested address is not valid in its context
2025-10-13 14:27:08,443 [DEBUG] Received PING from 192.168.0.107
2025-10-13 14:27:09,066 [ERROR] ping_peer failed for 192.168.0.107:0
Traceback (most recent call last):
  File "C:\Users\ASUS\OneDrive\Documents\chat_app1\chat_app_unified.py", line 506, in ping_peer
    s.connect((ip, port))
    ~~~~~~~~~^^^^^^^^^^^^
OSError: [WinError 10049] The requested address is not valid in its context
2025-10-13 14:27:13,506 [DEBUG] Received PING from 192.168.0.107
2025-10-13 14:27:14,073 [ERROR] ping_peer failed for 192.168.0.107:0
Traceback (most recent call last):
  File "C:\Users\ASUS\OneDrive\Documents\chat_app1\chat_app_unified.py", line 506, in ping_peer
    s.connect((ip, port))
    ~~~~~~~~~^^^^^^^^^^^^
OSError: [WinError 10049] The requested address is not valid in its context
2025-10-13 14:27:18,572 [DEBUG] Received PING from 192.168.0.107
2025-10-13 14:27:19,077 [ERROR] ping_peer failed for 192.168.0.107:0
Traceback (most recent call last):
  File "C:\Users\ASUS\OneDrive\Documents\chat_app1\chat_app_unified.py", line 506, in ping_peer
    s.connect((ip, port))
    ~~~~~~~~~^^^^^^^^^^^^
OSError: [WinError 10049] The requested address is not valid in its context
2025-10-13 14:27:23,634 [DEBUG] Received PING from 192.168.0.107
2025-10-13 14:27:24,082 [ERROR] ping_peer failed for 192.168.0.107:0
Traceback (most recent call last):
  File "C:\Users\ASUS\OneDrive\Documents\chat_app1\chat_app_unified.py", line 506, in ping_peer
    s.connect((ip, port))
    ~~~~~~~~~^^^^^^^^^^^^
OSError: [WinError 10049] The requested address is not valid in its context
2025-10-13 14:27:28,719 [DEBUG] Received PING from 192.168.0.107
2025-10-13 14:27:29,084 [ERROR] ping_peer failed for 192.168.0.107:0
Traceback (most recent call last):
  File "C:\Users\ASUS\OneDrive\Documents\chat_app1\chat_app_unified.py", line 506, in ping_peer
    s.connect((ip, port))
    ~~~~~~~~~^^^^^^^^^^^^
OSError: [WinError 10049] The requested address is not valid in its context
2025-10-13 14:27:33,779 [DEBUG] Received PING from 192.168.0.107
2025-10-13 14:27:34,086 [ERROR] ping_peer failed for 192.168.0.107:0
Traceback (most recent call last):
  File "C:\Users\ASUS\OneDrive\Documents\chat_app1\chat_app_unified.py", line 506, in ping_peer
    s.connect((ip, port))
    ~~~~~~~~~^^^^^^^^^^^^
OSError: [WinError 10049] The requested address is not valid in its context
2025-10-13 14:27:38,854 [DEBUG] Received PING from 192.168.0.107
2025-10-13 14:27:39,091 [ERROR] ping_peer failed for 192.168.0.107:0
Traceback (most recent call last):
  File "C:\Users\ASUS\OneDrive\Documents\chat_app1\chat_app_unified.py", line 506, in ping_peer
    s.connect((ip, port))
    ~~~~~~~~~^^^^^^^^^^^^
OSError: [WinError 10049] The requested address is not valid in its context
2025-10-13 14:27:43,936 [DEBUG] Received PING from 192.168.0.107
2025-10-13 14:27:44,097 [ERROR] ping_peer failed for 192.168.0.107:0
Traceback (most recent call last):
  File "C:\Users\ASUS\OneDrive\Documents\chat_app1\chat_app_unified.py", line 506, in ping_peer
    s.connect((ip, port))
    ~~~~~~~~~^^^^^^^^^^^^
OSError: [WinError 10049] The requested address is not valid in its context
2025-10-13 14:27:45,351 [INFO] Received message from 192.168.0.107
2025-10-13 14:27:49,037 [DEBUG] Received PING from 192.168.0.107
2025-10-13 14:27:49,102 [ERROR] ping_peer failed for 192.168.0.107:0
Traceback (most recent call last):
  File "C:\Users\ASUS\OneDrive\Documents\chat_app1\chat_app_unified.py", line 506, in ping_peer
    s.connect((ip, port))
    ~~~~~~~~~^^^^^^^^^^^^
OSError: [WinError 10049] The requested address is not valid in its context
2025-10-13 14:27:54,097 [DEBUG] Received PING from 192.168.0.107
2025-10-13 14:27:54,104 [ERROR] ping_peer failed for 192.168.0.107:0
Traceback (most recent call last):
  File "C:\Users\ASUS\OneDrive\Documents\chat_app1\chat_app_unified.py", line 506, in ping_peer
    s.connect((ip, port))
    ~~~~~~~~~^^^^^^^^^^^^
OSError: [WinError 10049] The requested address is not valid in its context
2025-10-13 14:27:58,235 [INFO] Received message from 192.168.0.107
2025-10-13 14:27:59,106 [ERROR] ping_peer failed for 192.168.0.107:0
Traceback (most recent call last):
  File "C:\Users\ASUS\OneDrive\Documents\chat_app1\chat_app_unified.py", line 506, in ping_peer
    s.connect((ip, port))
    ~~~~~~~~~^^^^^^^^^^^^
OSError: [WinError 10049] The requested address is not valid in its context
2025-10-13 14:27:59,173 [DEBUG] Received PING from 192.168.0.107
2025-10-13 14:28:00,166 [ERROR] send_message failed to 192.168.0.107:0
Traceback (most recent call last):
  File "C:\Users\ASUS\OneDrive\Documents\chat_app1\chat_app_unified.py", line 479, in send_message
    s.connect((ip, port))
    ~~~~~~~~~^^^^^^^^^^^^
OSError: [WinError 10049] The requested address is not valid in its context
2025-10-13 14:28:00,168 [WARNING] Send to 192.168.0.107 failed
2025-10-13 14:28:04,109 [ERROR] ping_peer failed for 192.168.0.107:0
Traceback (most recent call last):
  File "C:\Users\ASUS\OneDrive\Documents\chat_app1\chat_app_unified.py", line 506, in ping_peer
    s.connect((ip, port))
    ~~~~~~~~~^^^^^^^^^^^^
OSError: [WinError 10049] The requested address is not valid in its context
2025-10-13 14:28:04,238 [DEBUG] Received PING from 192.168.0.107
2025-10-13 14:28:09,112 [ERROR] ping_peer failed for 192.168.0.107:0
Traceback (most recent call last):
  File "C:\Users\ASUS\OneDrive\Documents\chat_app1\chat_app_unified.py", line 506, in ping_peer
    s.connect((ip, port))
    ~~~~~~~~~^^^^^^^^^^^^
OSError: [WinError 10049] The requested address is not valid in its context
2025-10-13 14:28:09,322 [DEBUG] Received PING from 192.168.0.107
2025-10-13 14:28:14,114 [ERROR] ping_peer failed for 192.168.0.107:0
Traceback (most recent call last):
  File "C:\Users\ASUS\OneDrive\Documents\chat_app1\chat_app_unified.py", line 506, in ping_peer
    s.connect((ip, port))
    ~~~~~~~~~^^^^^^^^^^^^
OSError: [WinError 10049] The requested address is not valid in its context
2025-10-13 14:28:19,120 [ERROR] ping_peer failed for 192.168.0.107:0
Traceback (most recent call last):
  File "C:\Users\ASUS\OneDrive\Documents\chat_app1\chat_app_unified.py", line 506, in ping_peer
    s.connect((ip, port))
    ~~~~~~~~~^^^^^^^^^^^^
OSError: [WinError 10049] The requested address is not valid in its context
2025-10-13 14:28:24,125 [ERROR] ping_peer failed for 192.168.0.107:0
Traceback (most recent call last):
  File "C:\Users\ASUS\OneDrive\Documents\chat_app1\chat_app_unified.py", line 506, in ping_peer
    s.connect((ip, port))
    ~~~~~~~~~^^^^^^^^^^^^
OSError: [WinError 10049] The requested address is not valid in its context
2025-10-13 14:28:29,127 [ERROR] ping_peer failed for 192.168.0.107:0
Traceback (most recent call last):
  File "C:\Users\ASUS\OneDrive\Documents\chat_app1\chat_app_unified.py", line 506, in ping_peer
    s.connect((ip, port))
    ~~~~~~~~~^^^^^^^^^^^^
OSError: [WinError 10049] The requested address is not valid in its context
2025-10-13 14:28:34,133 [ERROR] ping_peer failed for 192.168.0.107:0
Traceback (most recent call last):
  File "C:\Users\ASUS\OneDrive\Documents\chat_app1\chat_app_unified.py", line 506, in ping_peer
    s.connect((ip, port))
    ~~~~~~~~~^^^^^^^^^^^^
OSError: [WinError 10049] The requested address is not valid in its context
2025-10-13 14:28:39,139 [ERROR] ping_peer failed for 192.168.0.107:0
Traceback (most recent call last):
  File "C:\Users\ASUS\OneDrive\Documents\chat_app1\chat_app_unified.py", line 506, in ping_peer
    s.connect((ip, port))
    ~~~~~~~~~^^^^^^^^^^^^
OSError: [WinError 10049] The requested address is not valid in its context
2025-10-13 14:28:44,143 [ERROR] ping_peer failed for 192.168.0.107:0
Traceback (most recent call last):
  File "C:\Users\ASUS\OneDrive\Documents\chat_app1\chat_app_unified.py", line 506, in ping_peer
    s.connect((ip, port))
    ~~~~~~~~~^^^^^^^^^^^^
OSError: [WinError 10049] The requested address is not valid in its context
2025-10-13 14:28:49,146 [ERROR] ping_peer failed for 192.168.0.107:0
Traceback (most recent call last):
  File "C:\Users\ASUS\OneDrive\Documents\chat_app1\chat_app_unified.py", line 506, in ping_peer
    s.connect((ip, port))
    ~~~~~~~~~^^^^^^^^^^^^
OSError: [WinError 10049] The requested address is not valid in its context
2025-10-13 14:28:54,151 [ERROR] ping_peer failed for 192.168.0.107:0
Traceback (most recent call last):
  File "C:\Users\ASUS\OneDrive\Documents\chat_app1\chat_app_unified.py", line 506, in ping_peer
    s.connect((ip, port))
    ~~~~~~~~~^^^^^^^^^^^^
OSError: [WinError 10049] The requested address is not valid in its context
2025-10-13 14:28:59,153 [ERROR] ping_peer failed for 192.168.0.107:0
Traceback (most recent call last):
  File "C:\Users\ASUS\OneDrive\Documents\chat_app1\chat_app_unified.py", line 506, in ping_peer
    s.connect((ip, port))
    ~~~~~~~~~^^^^^^^^^^^^
OSError: [WinError 10049] The requested address is not valid in its context
2025-10-13 14:29:04,159 [ERROR] ping_peer failed for 192.168.0.107:0
Traceback (most recent call last):
  File "C:\Users\ASUS\OneDrive\Documents\chat_app1\chat_app_unified.py", line 506, in ping_peer
    s.connect((ip, port))
    ~~~~~~~~~^^^^^^^^^^^^
OSError: [WinError 10049] The requested address is not valid in its context
2025-10-13 14:29:09,164 [ERROR] ping_peer failed for 192.168.0.107:0
Traceback (most recent call last):
  File "C:\Users\ASUS\OneDrive\Documents\chat_app1\chat_app_unified.py", line 506, in ping_peer
    s.connect((ip, port))
    ~~~~~~~~~^^^^^^^^^^^^
OSError: [WinError 10049] The requested address is not valid in its context
2025-10-13 14:29:11,707 [DEBUG] Received PING from 192.168.0.107
2025-10-13 14:29:14,170 [ERROR] ping_peer failed for 192.168.0.107:0
Traceback (most recent call last):
  File "C:\Users\ASUS\OneDrive\Documents\chat_app1\chat_app_unified.py", line 506, in ping_peer
    s.connect((ip, port))
    ~~~~~~~~~^^^^^^^^^^^^
OSError: [WinError 10049] The requested address is not valid in its context
2025-10-13 14:29:16,837 [DEBUG] Received PING from 192.168.0.107
2025-10-13 14:29:19,174 [ERROR] ping_peer failed for 192.168.0.107:0
Traceback (most recent call last):
  File "C:\Users\ASUS\OneDrive\Documents\chat_app1\chat_app_unified.py", line 506, in ping_peer
    s.connect((ip, port))
    ~~~~~~~~~^^^^^^^^^^^^
OSError: [WinError 10049] The requested address is not valid in its context
2025-10-13 14:29:21,956 [DEBUG] Received PING from 192.168.0.107
2025-10-13 14:29:24,180 [ERROR] ping_peer failed for 192.168.0.107:0
Traceback (most recent call last):
  File "C:\Users\ASUS\OneDrive\Documents\chat_app1\chat_app_unified.py", line 506, in ping_peer
    s.connect((ip, port))
    ~~~~~~~~~^^^^^^^^^^^^
OSError: [WinError 10049] The requested address is not valid in its context
2025-10-13 14:29:27,104 [DEBUG] Received PING from 192.168.0.107
2025-10-13 14:29:29,182 [ERROR] ping_peer failed for 192.168.0.107:0
Traceback (most recent call last):
  File "C:\Users\ASUS\OneDrive\Documents\chat_app1\chat_app_unified.py", line 506, in ping_peer
    s.connect((ip, port))
    ~~~~~~~~~^^^^^^^^^^^^
OSError: [WinError 10049] The requested address is not valid in its context
2025-10-13 14:29:32,204 [DEBUG] Received PING from 192.168.0.107
2025-10-13 14:29:34,186 [ERROR] ping_peer failed for 192.168.0.107:0
Traceback (most recent call last):
  File "C:\Users\ASUS\OneDrive\Documents\chat_app1\chat_app_unified.py", line 506, in ping_peer
    s.connect((ip, port))
    ~~~~~~~~~^^^^^^^^^^^^
OSError: [WinError 10049] The requested address is not valid in its context
2025-10-13 14:29:37,374 [DEBUG] Received PING from 192.168.0.107
2025-10-13 14:29:37,465 [INFO] Received message from 192.168.0.107
2025-10-13 14:29:39,191 [ERROR] ping_peer failed for 192.168.0.107:0
Traceback (most recent call last):
  File "C:\Users\ASUS\OneDrive\Documents\chat_app1\chat_app_unified.py", line 506, in ping_peer
    s.connect((ip, port))
    ~~~~~~~~~^^^^^^^^^^^^
OSError: [WinError 10049] The requested address is not valid in its context
2025-10-13 14:29:43,310 [DEBUG] Received PING from 192.168.0.107
2025-10-13 14:29:44,194 [ERROR] ping_peer failed for 192.168.0.107:0
Traceback (most recent call last):
  File "C:\Users\ASUS\OneDrive\Documents\chat_app1\chat_app_unified.py", line 506, in ping_peer
    s.connect((ip, port))
    ~~~~~~~~~^^^^^^^^^^^^
OSError: [WinError 10049] The requested address is not valid in its context
2025-10-13 14:29:44,812 [ERROR] send_message failed to 192.168.0.107:0
Traceback (most recent call last):
  File "C:\Users\ASUS\OneDrive\Documents\chat_app1\chat_app_unified.py", line 479, in send_message
    s.connect((ip, port))
    ~~~~~~~~~^^^^^^^^^^^^
OSError: [WinError 10049] The requested address is not valid in its context
2025-10-13 14:29:44,814 [WARNING] Send to 192.168.0.107 failed
2025-10-13 14:29:48,450 [DEBUG] Received PING from 192.168.0.107
2025-10-13 14:29:49,199 [ERROR] ping_peer failed for 192.168.0.107:0
Traceback (most recent call last):
  File "C:\Users\ASUS\OneDrive\Documents\chat_app1\chat_app_unified.py", line 506, in ping_peer
    s.connect((ip, port))
    ~~~~~~~~~^^^^^^^^^^^^
OSError: [WinError 10049] The requested address is not valid in its context
2025-10-13 14:29:53,555 [DEBUG] Received PING from 192.168.0.107
2025-10-13 14:29:54,204 [ERROR] ping_peer failed for 192.168.0.107:0
Traceback (most recent call last):
  File "C:\Users\ASUS\OneDrive\Documents\chat_app1\chat_app_unified.py", line 506, in ping_peer
    s.connect((ip, port))
    ~~~~~~~~~^^^^^^^^^^^^
OSError: [WinError 10049] The requested address is not valid in its context
2025-10-13 14:30:01,926 [INFO] Starting p2p chat app. SHARED_KEY set: no
2025-10-13 14:30:01,972 [INFO] Bound to saved port 14447
2025-10-13 14:30:36,831 [INFO] User added peer 192.168.0.107:14447
2025-10-13 14:30:38,225 [DEBUG] Ping to 192.168.0.107 success 0 ms
2025-10-13 14:30:43,383 [DEBUG] Ping to 192.168.0.107 success 0 ms
2025-10-13 14:30:44,406 [INFO] Sent message to 192.168.0.107
2025-10-13 14:30:48,497 [DEBUG] Ping to 192.168.0.107 success 0 ms
2025-10-13 14:30:53,628 [DEBUG] Ping to 192.168.0.107 success 0 ms
2025-10-13 14:30:58,758 [DEBUG] Ping to 192.168.0.107 success 0 ms
2025-10-13 14:31:03,893 [DEBUG] Ping to 192.168.0.107 success 0 ms
2025-10-13 14:31:09,027 [DEBUG] Ping to 192.168.0.107 success 0 ms
2025-10-13 14:31:14,159 [DEBUG] Ping to 192.168.0.107 success 0 ms
2025-10-13 14:31:19,093 [INFO] Sent message to 192.168.0.107
2025-10-13 14:31:19,304 [DEBUG] Ping to 192.168.0.107 success 0 ms
2025-10-13 14:31:24,426 [DEBUG] Ping to 192.168.0.107 success 0 ms
2025-10-13 14:31:29,572 [DEBUG] Ping to 192.168.0.107 success 0 ms
2025-10-13 14:31:34,686 [DEBUG] Ping to 192.168.0.107 success 0 ms
2025-10-13 14:31:39,829 [DEBUG] Ping to 192.168.0.107 success 0 ms
2025-10-13 14:31:44,935 [DEBUG] Ping to 192.168.0.107 success 0 ms
2025-10-13 14:31:50,087 [DEBUG] Ping to 192.168.0.107 success 0 ms
2025-10-13 14:31:55,227 [DEBUG] Ping to 192.168.0.107 success 0 ms
2025-10-13 14:32:00,370 [DEBUG] Ping to 192.168.0.107 success 0 ms
2025-10-13 14:32:05,517 [DEBUG] Ping to 192.168.0.107 success 0 ms
2025-10-13 14:32:10,661 [DEBUG] Ping to 192.168.0.107 success 0 ms
2025-10-13 14:32:15,787 [DEBUG] Ping to 192.168.0.107 success 0 ms
2025-10-13 14:32:20,938 [DEBUG] Ping to 192.168.0.107 success 0 ms
2025-10-13 14:32:26,069 [DEBUG] Ping to 192.168.0.107 success 0 ms
2025-10-13 14:32:31,206 [DEBUG] Ping to 192.168.0.107 success 0 ms
2025-10-13 14:32:36,336 [DEBUG] Ping to 192.168.0.107 success 0 ms
2025-10-13 14:32:41,468 [DEBUG] Ping to 192.168.0.107 success 0 ms
2025-10-13 14:32:49,482 [ERROR] ping_peer failed for 192.168.0.107:14447
Traceback (most recent call last):
  File "C:\Users\ASUS\OneDrive\Documents\chat_app1\chat_app_unified.py", line 506, in ping_peer
    s.connect((ip, port))
    ~~~~~~~~~^^^^^^^^^^^^
TimeoutError: timed out
2025-10-13 14:32:57,494 [ERROR] ping_peer failed for 192.168.0.107:14447
Traceback (most recent call last):
  File "C:\Users\ASUS\OneDrive\Documents\chat_app1\chat_app_unified.py", line 506, in ping_peer
    s.connect((ip, port))
    ~~~~~~~~~^^^^^^^^^^^^
TimeoutError: timed out
2025-10-13 14:33:05,498 [ERROR] ping_peer failed for 192.168.0.107:14447
Traceback (most recent call last):
  File "C:\Users\ASUS\OneDrive\Documents\chat_app1\chat_app_unified.py", line 506, in ping_peer
    s.connect((ip, port))
    ~~~~~~~~~^^^^^^^^^^^^
TimeoutError: timed out
2025-10-13 14:44:57,711 [INFO] Starting p2p chat app. SHARED_KEY set: no
2025-10-13 14:44:57,761 [INFO] Bound to saved port 14447
2025-10-15 00:19:46,658 [INFO] Starting p2p chat app. SHARED_KEY set: no
2025-10-15 00:19:46,989 [INFO] Selected new random port 10834 and saved to listen_port_DESKTOP-OBIM9JD.txt
2025-10-15 00:20:22,272 [DEBUG] Ping to 192.168.1.53 success 0 ms
2025-10-15 00:20:22,697 [INFO] User added peer 192.168.1.53:57023
2025-10-15 00:20:27,296 [DEBUG] Ping to 192.168.1.53 success 0 ms
2025-10-15 00:20:29,911 [INFO] Sent message to 192.168.1.53
2025-10-15 00:20:32,731 [DEBUG] Ping to 192.168.1.53 success 0 ms
2025-10-15 00:20:40,746 [ERROR] ping_peer failed for 192.168.1.53:57023
Traceback (most recent call last):
  File "C:\Users\ASUS\OneDrive\Documents\chat_app1\chat_app_unified.py", line 690, in ping_peer
    s.connect((ip, port))
    ~~~~~~~~~^^^^^^^^^^^^
TimeoutError: timed out
2025-10-15 00:20:45,813 [DEBUG] Ping to 192.168.1.53 success 0 ms
2025-10-15 00:20:50,857 [DEBUG] Ping to 192.168.1.53 success 0 ms
2025-10-15 00:20:58,192 [DEBUG] Ping to 192.168.1.53 success 0 ms
2025-10-15 00:21:04,647 [DEBUG] Ping to 192.168.1.53 success 0 ms
2025-10-15 00:21:09,677 [DEBUG] Ping to 192.168.1.53 success 0 ms
2025-10-15 00:21:14,709 [DEBUG] Ping to 192.168.1.53 success 0 ms
2025-10-15 00:21:19,740 [DEBUG] Ping to 192.168.1.53 success 0 ms
2025-10-15 00:21:24,828 [DEBUG] Ping to 192.168.1.53 success 0 ms
2025-10-15 00:21:29,855 [DEBUG] Ping to 192.168.1.53 success 0 ms
2025-10-15 00:21:36,950 [ERROR] ping_peer failed for 192.168.1.53:57023
Traceback (most recent call last):
  File "C:\Users\ASUS\OneDrive\Documents\chat_app1\chat_app_unified.py", line 690, in ping_peer
    s.connect((ip, port))
    ~~~~~~~~~^^^^^^^^^^^^
ConnectionRefusedError: [WinError 10061] No connection could be made because the target machine actively refused it
2025-10-15 00:21:44,968 [ERROR] ping_peer failed for 192.168.1.53:57023
Traceback (most recent call last):
  File "C:\Users\ASUS\OneDrive\Documents\chat_app1\chat_app_unified.py", line 690, in ping_peer
    s.connect((ip, port))
    ~~~~~~~~~^^^^^^^^^^^^
TimeoutError: timed out
2025-10-15 00:21:52,094 [ERROR] ping_peer failed for 192.168.1.53:57023
Traceback (most recent call last):
  File "C:\Users\ASUS\OneDrive\Documents\chat_app1\chat_app_unified.py", line 690, in ping_peer
    s.connect((ip, port))
    ~~~~~~~~~^^^^^^^^^^^^
ConnectionRefusedError: [WinError 10061] No connection could be made because the target machine actively refused it
2025-10-15 00:22:00,110 [ERROR] ping_peer failed for 192.168.1.53:57023
Traceback (most recent call last):
  File "C:\Users\ASUS\OneDrive\Documents\chat_app1\chat_app_unified.py", line 690, in ping_peer
    s.connect((ip, port))
    ~~~~~~~~~^^^^^^^^^^^^
TimeoutError: timed out
2025-10-15 00:22:08,125 [ERROR] ping_peer failed for 192.168.1.53:57023
Traceback (most recent call last):
  File "C:\Users\ASUS\OneDrive\Documents\chat_app1\chat_app_unified.py", line 690, in ping_peer
    s.connect((ip, port))
    ~~~~~~~~~^^^^^^^^^^^^
TimeoutError: timed out
2025-10-15 00:22:16,141 [ERROR] ping_peer failed for 192.168.1.53:57023
Traceback (most recent call last):
  File "C:\Users\ASUS\OneDrive\Documents\chat_app1\chat_app_unified.py", line 690, in ping_peer
    s.connect((ip, port))
    ~~~~~~~~~^^^^^^^^^^^^
TimeoutError: timed out
2025-10-15 00:22:24,156 [ERROR] ping_peer failed for 192.168.1.53:57023
Traceback (most recent call last):
  File "C:\Users\ASUS\OneDrive\Documents\chat_app1\chat_app_unified.py", line 690, in ping_peer
    s.connect((ip, port))
    ~~~~~~~~~^^^^^^^^^^^^
TimeoutError: timed out
2025-10-15 00:22:32,172 [ERROR] ping_peer failed for 192.168.1.53:57023
Traceback (most recent call last):
  File "C:\Users\ASUS\OneDrive\Documents\chat_app1\chat_app_unified.py", line 690, in ping_peer
    s.connect((ip, port))
    ~~~~~~~~~^^^^^^^^^^^^
TimeoutError: timed out
2025-10-15 00:22:40,188 [ERROR] ping_peer failed for 192.168.1.53:57023
Traceback (most recent call last):
  File "C:\Users\ASUS\OneDrive\Documents\chat_app1\chat_app_unified.py", line 690, in ping_peer
    s.connect((ip, port))
    ~~~~~~~~~^^^^^^^^^^^^
TimeoutError: timed out
2025-10-15 00:22:48,203 [ERROR] ping_peer failed for 192.168.1.53:57023
Traceback (most recent call last):
  File "C:\Users\ASUS\OneDrive\Documents\chat_app1\chat_app_unified.py", line 690, in ping_peer
    s.connect((ip, port))
    ~~~~~~~~~^^^^^^^^^^^^
TimeoutError: timed out
2025-10-15 00:22:56,219 [ERROR] ping_peer failed for 192.168.1.53:57023
Traceback (most recent call last):
  File "C:\Users\ASUS\OneDrive\Documents\chat_app1\chat_app_unified.py", line 690, in ping_peer
    s.connect((ip, port))
    ~~~~~~~~~^^^^^^^^^^^^
TimeoutError: timed out
2025-10-15 00:23:04,250 [ERROR] ping_peer failed for 192.168.1.53:57023
Traceback (most recent call last):
  File "C:\Users\ASUS\OneDrive\Documents\chat_app1\chat_app_unified.py", line 690, in ping_peer
    s.connect((ip, port))
    ~~~~~~~~~^^^^^^^^^^^^
TimeoutError: timed out
2025-10-15 00:23:12,266 [ERROR] ping_peer failed for 192.168.1.53:57023
Traceback (most recent call last):
  File "C:\Users\ASUS\OneDrive\Documents\chat_app1\chat_app_unified.py", line 690, in ping_peer
    s.connect((ip, port))
    ~~~~~~~~~^^^^^^^^^^^^
TimeoutError: timed out
2025-10-15 00:23:20,281 [ERROR] ping_peer failed for 192.168.1.53:57023
Traceback (most recent call last):
  File "C:\Users\ASUS\OneDrive\Documents\chat_app1\chat_app_unified.py", line 690, in ping_peer
    s.connect((ip, port))
    ~~~~~~~~~^^^^^^^^^^^^
TimeoutError: timed out
2025-10-15 00:23:28,297 [ERROR] ping_peer failed for 192.168.1.53:57023
Traceback (most recent call last):
  File "C:\Users\ASUS\OneDrive\Documents\chat_app1\chat_app_unified.py", line 690, in ping_peer
    s.connect((ip, port))
    ~~~~~~~~~^^^^^^^^^^^^
TimeoutError: timed out
2025-10-15 00:23:36,311 [ERROR] ping_peer failed for 192.168.1.53:57023
Traceback (most recent call last):
  File "C:\Users\ASUS\OneDrive\Documents\chat_app1\chat_app_unified.py", line 690, in ping_peer
    s.connect((ip, port))
    ~~~~~~~~~^^^^^^^^^^^^
TimeoutError: timed out
